<?xml version="1.0" ?>
<robot name="Untitled" xmlns:xacro="http://www.ros.org/wiki/xacro">

<xacro:include filename="$(find Untitled_description)/urdf/materials.xacro" />
<xacro:include filename="$(find Untitled_description)/urdf/Untitled.trans" />
<xacro:include filename="$(find Untitled_description)/urdf/Untitled.gazebo" />
<link name="base_link">
  <inertial>
    <origin xyz="-0.0027038397852555225 -5.423781482548487e-07 0.03174826003804549" rpy="0 0 0"/>
    <mass value="1.5829941031835308"/>
    <inertia ixx="0.002267" iyy="0.002381" izz="0.003913" ixy="0.0" iyz="-0.0" ixz="-3.2e-05"/>
  </inertial>
  <visual>
    <origin xyz="0 0 0" rpy="0 0 0"/>
    <geometry>
      <mesh filename="package://Untitled_description/meshes/base_link.stl" scale="0.001 0.001 0.001"/>
    </geometry>
    <material name="silver"/>
  </visual>
  <collision>
    <origin xyz="0 0 0" rpy="0 0 0"/>
    <geometry>
      <mesh filename="package://Untitled_description/meshes/base_link.stl" scale="0.001 0.001 0.001"/>
    </geometry>
  </collision>
</link>

<link name="link_1__1">
  <inertial>
    <origin xyz="-0.007277512033058122 4.8763026692895006e-05 0.011631486838158726" rpy="0 0 0"/>
    <mass value="0.6495824188722104"/>
    <inertia ixx="0.000323" iyy="0.000392" izz="0.000536" ixy="1e-06" iyz="-1e-06" ixz="7.9e-05"/>
  </inertial>
  <visual>
    <origin xyz="-9.9e-05 1e-06 -0.051" rpy="0 0 0"/>
    <geometry>
      <mesh filename="package://Untitled_description/meshes/link_1__1.stl" scale="0.001 0.001 0.001"/>
    </geometry>
    <material name="silver"/>
  </visual>
  <collision>
    <origin xyz="-9.9e-05 1e-06 -0.051" rpy="0 0 0"/>
    <geometry>
      <mesh filename="package://Untitled_description/meshes/link_1__1.stl" scale="0.001 0.001 0.001"/>
    </geometry>
  </collision>
</link>

<link name="link_3_1">
  <inertial>
    <origin xyz="0.0192845282791872 0.08685469809762955 -3.156043858915103e-05" rpy="0 0 0"/>
    <mass value="1.4865137140753586"/>
    <inertia ixx="0.003842" iyy="0.000685" izz="0.004094" ixy="-0.000824" iyz="3e-06" ixz="0.0"/>
  </inertial>
  <visual>
    <origin xyz="0.021561 -0.06222 -0.300343" rpy="0 0 0"/>
    <geometry>
      <mesh filename="package://Untitled_description/meshes/link_3_1.stl" scale="0.001 0.001 0.001"/>
    </geometry>
    <material name="silver"/>
  </visual>
  <collision>
    <origin xyz="0.021561 -0.06222 -0.300343" rpy="0 0 0"/>
    <geometry>
      <mesh filename="package://Untitled_description/meshes/link_3_1.stl" scale="0.001 0.001 0.001"/>
    </geometry>
  </collision>
</link>

<link name="link_4_1">
  <inertial>
    <origin xyz="0.007813210338647607 0.05502777991911034 -0.0014764267544294385" rpy="0 0 0"/>
    <mass value="0.7277784603492614"/>
    <inertia ixx="0.001233" iyy="0.000251" izz="0.001273" ixy="-0.00032" iyz="9.3e-05" ixz="2.3e-05"/>
  </inertial>
  <visual>
    <origin xyz="0.021153 -0.212439 -0.300151" rpy="0 0 0"/>
    <geometry>
      <mesh filename="package://Untitled_description/meshes/link_4_1.stl" scale="0.001 0.001 0.001"/>
    </geometry>
    <material name="silver"/>
  </visual>
  <collision>
    <origin xyz="0.021153 -0.212439 -0.300151" rpy="0 0 0"/>
    <geometry>
      <mesh filename="package://Untitled_description/meshes/link_4_1.stl" scale="0.001 0.001 0.001"/>
    </geometry>
  </collision>
</link>

<link name="link_5__1">
  <inertial>
    <origin xyz="-0.0077871703186344465 0.041438327284405274 0.0013652582724152929" rpy="0 0 0"/>
    <mass value="0.11824706989499154"/>
    <inertia ixx="7.6e-05" iyy="7e-06" izz="7.4e-05" ixy="1e-06" iyz="1.2e-05" ixz="0.0"/>
  </inertial>
  <visual>
    <origin xyz="-0.01425 -0.291717 -0.317051" rpy="0 0 0"/>
    <geometry>
      <mesh filename="package://Untitled_description/meshes/link_5__1.stl" scale="0.001 0.001 0.001"/>
    </geometry>
    <material name="silver"/>
  </visual>
  <collision>
    <origin xyz="-0.01425 -0.291717 -0.317051" rpy="0 0 0"/>
    <geometry>
      <mesh filename="package://Untitled_description/meshes/link_5__1.stl" scale="0.001 0.001 0.001"/>
    </geometry>
  </collision>
</link>

<link name="link_2_1">
  <inertial>
    <origin xyz="0.027286924725137916 0.012329686820526884 0.13082314360398872" rpy="0 0 0"/>
    <mass value="2.3683472111587176"/>
    <inertia ixx="0.017119" iyy="0.01594" izz="0.001914" ixy="-3.2e-05" iyz="-0.002492" ixz="-1e-05"/>
  </inertial>
  <visual>
    <origin xyz="0.021599 -0.000328 -0.083958" rpy="0 0 0"/>
    <geometry>
      <mesh filename="package://Untitled_description/meshes/link_2_1.stl" scale="0.001 0.001 0.001"/>
    </geometry>
    <material name="silver"/>
  </visual>
  <collision>
    <origin xyz="0.021599 -0.000328 -0.083958" rpy="0 0 0"/>
    <geometry>
      <mesh filename="package://Untitled_description/meshes/link_2_1.stl" scale="0.001 0.001 0.001"/>
    </geometry>
  </collision>
</link>

<joint name="Revolute 1" type="revolute">
  <origin xyz="9.9e-05 -1e-06 0.051" rpy="0 0 0"/>
  <parent link="base_link"/>
  <child link="link_1__1"/>
  <axis xyz="-0.0 0.0 -1.0"/>
  <limit upper="1.570796" lower="-1.570796" effort="100" velocity="100"/>
</joint>

<joint name="Revolute 2" type="revolute">
  <origin xyz="3.8e-05 0.061892 0.216385" rpy="0 0 0"/>
  <parent link="link_2_1"/>
  <child link="link_3_1"/>
  <axis xyz="-1.0 0.0 0.0"/>
  <limit upper="1.570796" lower="-1.570796" effort="100" velocity="100"/>
</joint>

<joint name="Revolute 4" type="revolute">
  <origin xyz="0.000408 0.150219 -0.000192" rpy="0 0 0"/>
  <parent link="link_3_1"/>
  <child link="link_4_1"/>
  <axis xyz="-1.0 -0.0 0.0"/>
  <limit upper="1.570796" lower="-1.570796" effort="100" velocity="100"/>
</joint>

<joint name="Revolute 5" type="revolute">
  <origin xyz="0.035403 0.079278 0.0169" rpy="0 0 0"/>
  <parent link="link_4_1"/>
  <child link="link_5__1"/>
  <axis xyz="1.0 0.0 -0.0"/>
  <limit upper="1.570796" lower="-1.570796" effort="100" velocity="100"/>
</joint>

<joint name="Revolute 6" type="revolute">
  <origin xyz="-0.021698 0.000329 0.032958" rpy="0 0 0"/>
  <parent link="link_1__1"/>
  <child link="link_2_1"/>
  <axis xyz="-1.0 0.0 -0.0"/>
  <limit upper="1.570796" lower="-1.570796" effort="100" velocity="100"/>
</joint>

</robot>
